[2024-12-22T10:30:07.379+0000] {local_task_job_runner.py:123} INFO - ::group::Pre task execution logs
[2024-12-22T10:30:07.429+0000] {taskinstance.py:2613} INFO - Dependencies all met for dep_context=non-requeueable deps ti=<TaskInstance: fetch_and_store_music_albums.create_table scheduled__2024-12-17T00:00:00+00:00 [queued]>
[2024-12-22T10:30:07.450+0000] {taskinstance.py:2613} INFO - Dependencies all met for dep_context=requeueable deps ti=<TaskInstance: fetch_and_store_music_albums.create_table scheduled__2024-12-17T00:00:00+00:00 [queued]>
[2024-12-22T10:30:07.455+0000] {taskinstance.py:2866} INFO - Starting attempt 2 of 2
[2024-12-22T10:30:07.495+0000] {taskinstance.py:2889} INFO - Executing <Task(PostgresOperator): create_table> on 2024-12-17 00:00:00+00:00
[2024-12-22T10:30:07.513+0000] {warnings.py:112} WARNING - /home/***/.local/lib/python3.12/site-packages/***/task/task_runner/standard_task_runner.py:70: DeprecationWarning: This process (pid=3645) is multi-threaded, use of fork() may lead to deadlocks in the child.
  pid = os.fork()

[2024-12-22T10:30:07.517+0000] {standard_task_runner.py:104} INFO - Running: ['***', 'tasks', 'run', 'fetch_and_store_music_albums', 'create_table', 'scheduled__2024-12-17T00:00:00+00:00', '--job-id', '57', '--raw', '--subdir', 'DAGS_FOLDER/app.py', '--cfg-path', '/tmp/tmprq6udiw3']
[2024-12-22T10:30:07.518+0000] {standard_task_runner.py:72} INFO - Started process 3665 to run task
[2024-12-22T10:30:07.518+0000] {standard_task_runner.py:105} INFO - Job 57: Subtask create_table
[2024-12-22T10:30:07.643+0000] {task_command.py:467} INFO - Running <TaskInstance: fetch_and_store_music_albums.create_table scheduled__2024-12-17T00:00:00+00:00 [running]> on host 8314332f533c
[2024-12-22T10:30:07.804+0000] {taskinstance.py:3132} INFO - Exporting env vars: AIRFLOW_CTX_DAG_OWNER='***' AIRFLOW_CTX_DAG_ID='fetch_and_store_music_albums' AIRFLOW_CTX_TASK_ID='create_table' AIRFLOW_CTX_EXECUTION_DATE='2024-12-17T00:00:00+00:00' AIRFLOW_CTX_TRY_NUMBER='2' AIRFLOW_CTX_DAG_RUN_ID='scheduled__2024-12-17T00:00:00+00:00'
[2024-12-22T10:30:07.808+0000] {logging_mixin.py:190} INFO - Task instance is in running state
[2024-12-22T10:30:07.809+0000] {logging_mixin.py:190} INFO -  Previous state of the Task instance: queued
[2024-12-22T10:30:07.810+0000] {logging_mixin.py:190} INFO - Current task name:create_table state:running start_date:2024-12-22 10:30:07.430884+00:00
[2024-12-22T10:30:07.811+0000] {logging_mixin.py:190} INFO - Dag name:fetch_and_store_music_albums and current dag run status:running
[2024-12-22T10:30:07.812+0000] {taskinstance.py:731} INFO - ::endgroup::
[2024-12-22T10:30:07.812+0000] {sql.py:278} INFO - Executing: 
    CREATE TABLE IF NOT EXISTS albums (
        id SERIAL PRIMARY KEY,
        title TEXT NOT NULL,
        artist TEXT,
        price TEXT,
        release_date TEXT,
        rating TEXT
    );
    
[2024-12-22T10:30:07.825+0000] {base.py:84} INFO - Retrieving connection 'music_connection'
[2024-12-22T10:30:07.837+0000] {base.py:84} INFO - Retrieving connection 'music_connection'
[2024-12-22T10:30:07.843+0000] {taskinstance.py:3311} ERROR - Task failed with exception
Traceback (most recent call last):
  File "/home/airflow/.local/lib/python3.12/site-packages/airflow/models/taskinstance.py", line 767, in _execute_task
    result = _execute_callable(context=context, **execute_callable_kwargs)
             ^^^^^^^^^^^^^^^^^^^^^^^^^^^^^^^^^^^^^^^^^^^^^^^^^^^^^^^^^^^^^
  File "/home/airflow/.local/lib/python3.12/site-packages/airflow/models/taskinstance.py", line 733, in _execute_callable
    return ExecutionCallableRunner(
           ^^^^^^^^^^^^^^^^^^^^^^^^
  File "/home/airflow/.local/lib/python3.12/site-packages/airflow/utils/operator_helpers.py", line 252, in run
    return self.func(*args, **kwargs)
           ^^^^^^^^^^^^^^^^^^^^^^^^^^
  File "/home/airflow/.local/lib/python3.12/site-packages/airflow/models/baseoperator.py", line 422, in wrapper
    return func(self, *args, **kwargs)
           ^^^^^^^^^^^^^^^^^^^^^^^^^^^
  File "/home/airflow/.local/lib/python3.12/site-packages/airflow/providers/common/sql/operators/sql.py", line 284, in execute
    output = hook.run(
             ^^^^^^^^^
  File "/home/airflow/.local/lib/python3.12/site-packages/airflow/providers/common/sql/hooks/sql.py", line 494, in run
    with self._create_autocommit_connection(autocommit) as conn:
         ^^^^^^^^^^^^^^^^^^^^^^^^^^^^^^^^^^^^^^^^^^^^^^
  File "/usr/local/lib/python3.12/contextlib.py", line 137, in __enter__
    return next(self.gen)
           ^^^^^^^^^^^^^^
  File "/home/airflow/.local/lib/python3.12/site-packages/airflow/providers/common/sql/hooks/sql.py", line 618, in _create_autocommit_connection
    with closing(self.get_conn()) as conn:
                 ^^^^^^^^^^^^^^^
  File "/home/airflow/.local/lib/python3.12/site-packages/airflow/providers/postgres/hooks/postgres.py", line 189, in get_conn
    self.conn = psycopg2.connect(**conn_args)
                ^^^^^^^^^^^^^^^^^^^^^^^^^^^^^
  File "/home/airflow/.local/lib/python3.12/site-packages/psycopg2/__init__.py", line 122, in connect
    conn = _connect(dsn, connection_factory=connection_factory, **kwasync)
           ^^^^^^^^^^^^^^^^^^^^^^^^^^^^^^^^^^^^^^^^^^^^^^^^^^^^^^^^^^^^^^^
psycopg2.OperationalError: connection to server at "172.19.0.3", port 5432 failed: FATAL:  database "amazon_books" does not exist

[2024-12-22T10:30:07.857+0000] {logging_mixin.py:190} INFO - Task instance in failure state
[2024-12-22T10:30:07.858+0000] {logging_mixin.py:190} INFO - Task start:2024-12-22 10:30:07.430884+00:00 end:2024-12-22 10:30:07.856681+00:00 duration:0.425797
[2024-12-22T10:30:07.859+0000] {logging_mixin.py:190} INFO - Task:<Task(PostgresOperator): create_table> dag:<DAG: fetch_and_store_music_albums> dagrun:<DagRun fetch_and_store_music_albums @ 2024-12-17 00:00:00+00:00: scheduled__2024-12-17T00:00:00+00:00, state:running, queued_at: 2024-12-22 10:24:57.871147+00:00. externally triggered: False>
[2024-12-22T10:30:07.860+0000] {logging_mixin.py:190} INFO - Failure caused by connection to server at "172.19.0.3", port 5432 failed: FATAL:  database "amazon_books" does not exist
[2024-12-22T10:30:07.861+0000] {taskinstance.py:1225} INFO - Marking task as FAILED. dag_id=fetch_and_store_music_albums, task_id=create_table, run_id=scheduled__2024-12-17T00:00:00+00:00, execution_date=20241217T000000, start_date=20241222T103007, end_date=20241222T103007
[2024-12-22T10:30:07.895+0000] {taskinstance.py:340} INFO - ::group::Post task execution logs
[2024-12-22T10:30:07.896+0000] {standard_task_runner.py:124} ERROR - Failed to execute job 57 for task create_table (connection to server at "172.19.0.3", port 5432 failed: FATAL:  database "amazon_books" does not exist
; 3665)
Traceback (most recent call last):
  File "/home/airflow/.local/lib/python3.12/site-packages/airflow/task/task_runner/standard_task_runner.py", line 117, in _start_by_fork
    ret = args.func(args, dag=self.dag)
          ^^^^^^^^^^^^^^^^^^^^^^^^^^^^^
  File "/home/airflow/.local/lib/python3.12/site-packages/airflow/cli/cli_config.py", line 49, in command
    return func(*args, **kwargs)
           ^^^^^^^^^^^^^^^^^^^^^
  File "/home/airflow/.local/lib/python3.12/site-packages/airflow/utils/cli.py", line 116, in wrapper
    return f(*args, **kwargs)
           ^^^^^^^^^^^^^^^^^^
  File "/home/airflow/.local/lib/python3.12/site-packages/airflow/cli/commands/task_command.py", line 483, in task_run
    task_return_code = _run_task_by_selected_method(args, _dag, ti)
                       ^^^^^^^^^^^^^^^^^^^^^^^^^^^^^^^^^^^^^^^^^^^^
  File "/home/airflow/.local/lib/python3.12/site-packages/airflow/cli/commands/task_command.py", line 256, in _run_task_by_selected_method
    return _run_raw_task(args, ti)
           ^^^^^^^^^^^^^^^^^^^^^^^
  File "/home/airflow/.local/lib/python3.12/site-packages/airflow/cli/commands/task_command.py", line 341, in _run_raw_task
    return ti._run_raw_task(
           ^^^^^^^^^^^^^^^^^
  File "/home/airflow/.local/lib/python3.12/site-packages/airflow/utils/session.py", line 97, in wrapper
    return func(*args, session=session, **kwargs)
           ^^^^^^^^^^^^^^^^^^^^^^^^^^^^^^^^^^^^^^
  File "/home/airflow/.local/lib/python3.12/site-packages/airflow/models/taskinstance.py", line 3005, in _run_raw_task
    return _run_raw_task(
           ^^^^^^^^^^^^^^
  File "/home/airflow/.local/lib/python3.12/site-packages/airflow/models/taskinstance.py", line 273, in _run_raw_task
    TaskInstance._execute_task_with_callbacks(
  File "/home/airflow/.local/lib/python3.12/site-packages/airflow/models/taskinstance.py", line 3159, in _execute_task_with_callbacks
    result = self._execute_task(context, task_orig)
             ^^^^^^^^^^^^^^^^^^^^^^^^^^^^^^^^^^^^^^
  File "/home/airflow/.local/lib/python3.12/site-packages/airflow/models/taskinstance.py", line 3183, in _execute_task
    return _execute_task(self, context, task_orig)
           ^^^^^^^^^^^^^^^^^^^^^^^^^^^^^^^^^^^^^^^
  File "/home/airflow/.local/lib/python3.12/site-packages/airflow/models/taskinstance.py", line 767, in _execute_task
    result = _execute_callable(context=context, **execute_callable_kwargs)
             ^^^^^^^^^^^^^^^^^^^^^^^^^^^^^^^^^^^^^^^^^^^^^^^^^^^^^^^^^^^^^
  File "/home/airflow/.local/lib/python3.12/site-packages/airflow/models/taskinstance.py", line 733, in _execute_callable
    return ExecutionCallableRunner(
           ^^^^^^^^^^^^^^^^^^^^^^^^
  File "/home/airflow/.local/lib/python3.12/site-packages/airflow/utils/operator_helpers.py", line 252, in run
    return self.func(*args, **kwargs)
           ^^^^^^^^^^^^^^^^^^^^^^^^^^
  File "/home/airflow/.local/lib/python3.12/site-packages/airflow/models/baseoperator.py", line 422, in wrapper
    return func(self, *args, **kwargs)
           ^^^^^^^^^^^^^^^^^^^^^^^^^^^
  File "/home/airflow/.local/lib/python3.12/site-packages/airflow/providers/common/sql/operators/sql.py", line 284, in execute
    output = hook.run(
             ^^^^^^^^^
  File "/home/airflow/.local/lib/python3.12/site-packages/airflow/providers/common/sql/hooks/sql.py", line 494, in run
    with self._create_autocommit_connection(autocommit) as conn:
         ^^^^^^^^^^^^^^^^^^^^^^^^^^^^^^^^^^^^^^^^^^^^^^
  File "/usr/local/lib/python3.12/contextlib.py", line 137, in __enter__
    return next(self.gen)
           ^^^^^^^^^^^^^^
  File "/home/airflow/.local/lib/python3.12/site-packages/airflow/providers/common/sql/hooks/sql.py", line 618, in _create_autocommit_connection
    with closing(self.get_conn()) as conn:
                 ^^^^^^^^^^^^^^^
  File "/home/airflow/.local/lib/python3.12/site-packages/airflow/providers/postgres/hooks/postgres.py", line 189, in get_conn
    self.conn = psycopg2.connect(**conn_args)
                ^^^^^^^^^^^^^^^^^^^^^^^^^^^^^
  File "/home/airflow/.local/lib/python3.12/site-packages/psycopg2/__init__.py", line 122, in connect
    conn = _connect(dsn, connection_factory=connection_factory, **kwasync)
           ^^^^^^^^^^^^^^^^^^^^^^^^^^^^^^^^^^^^^^^^^^^^^^^^^^^^^^^^^^^^^^^
psycopg2.OperationalError: connection to server at "172.19.0.3", port 5432 failed: FATAL:  database "amazon_books" does not exist

[2024-12-22T10:30:07.950+0000] {local_task_job_runner.py:266} INFO - Task exited with return code 1
[2024-12-22T10:30:07.997+0000] {taskinstance.py:3895} INFO - 0 downstream tasks scheduled from follow-on schedule check
[2024-12-22T10:30:08.013+0000] {local_task_job_runner.py:245} INFO - ::endgroup::
